<?xml version="1.0"?>
<robot xmlns:xacro="http://www.ros.org/wiki/xacro">
    <xacro:macro name="wheel_xacro" params="wheel_name xyz">
        <link name="${wheel_name}_wheel_link">
            <visual>
                <!-- 将r调整为90度，将轮子竖起来？这表示正确吗？ 是的， 竖起来的表示是正确的 -->
                <!-- 此处，构建了原始的轮子样子 -->
                <origin xyz="0 0 0" rpy="1.57079 0 0" /> 
                <geometry>
                    <cylinder length="0.04" radius="0.032" />
                </geometry>
                <material name="yellow">
                    <color rgba="1.0 1.0 0.0 0.8" />
                </material>
            </visual>
        </link>
        
        <!-- continuous 连续转动关节，对应轮子的旋转关节（主要指定旋转轴线），关节类型：固定和连续 -->
        <joint name="${wheel_name}_wheel_joint" type="continuous">
            <parent link="base_link" />
            <child link="${wheel_name}_wheel_link" />
            <!-- 指定该关节的坐标位置 -->
            <origin xyz="${xyz}" />
            <!-- axis定义关节的旋转轴方向，其 xyz 值对应机器人基坐标系（base_link）的 X、Y、Z 轴分量。 -->
            <!-- axis 方向：axis="0 1 0" = 关节旋转轴线沿 Y 轴，对应轮子滚动的轴线，符合行进轮需求 -->
            <!-- 与continuous向对应 -->
            <axis xyz="0 1 0" />
        </joint>
    </xacro:macro>
</robot>